Workbook
Name BED_FIXED_COST: Inputs!$B$21
Name BLENDED_LABOR_RATE: CostStructure!$B$9
Name CAR_BEDS: Optimization!$B$3
Name CAR_DIM_PCT: Inputs!$B$11
Name CAR_FERT_COST: Inputs!$B$10
Name CAR_HRS: Inputs!$B$9
Name CAR_MAX_BEDS: Inputs!$B$7
Name CAR_PRICE: Inputs!$B$8
Name FARMER_HOURS: Inputs!$B$18
Name FARMER_HOURS_USED: CostStructure!$B$3
Name FARMER_LABOR_COST: CostStructure!$B$6
Name FARMER_RATE: Inputs!$B$24
Name FARMER_SALARY: Inputs!$B$23
Name FARMER_SEASON_HRS: Inputs!$B$22
Name MAX_TEMP_WORKERS: Inputs!$B$20
Name MES_BEDS: Optimization!$B$4
Name MES_DIM_PCT: Inputs!$B$16
Name MES_FERT_COST: Inputs!$B$15
Name MES_HRS: Inputs!$B$14
Name MES_MAX_BEDS: Inputs!$B$12
Name MES_PRICE: Inputs!$B$13
Name OPT_CAR_BEDS: Optimization!$B$9
Name OPT_MES_BEDS: Optimization!$B$10
Name OPT_TOM_BEDS: Optimization!$B$8
Name SEASON_WEEKS: Inputs!$B$27
Name TEMP_COST_EACH: Inputs!$B$25
Name TEMP_HOURS_USED: CostStructure!$B$4
Name TEMP_LABOR_COST: CostStructure!$B$7
Name TEMP_RATE: Inputs!$B$26
Name TEMP_WORKER_HOURS: Inputs!$B$19
Name TEMP_WORKERS_USED: Optimization!$B$18
Name TEMP_WORKERS_USED_CALC: CostStructure!$B$5
Name TOM_BEDS: Optimization!$B$2
Name TOM_DIM_PCT: Inputs!$B$6
Name TOM_FERT_COST: Inputs!$B$5
Name TOM_HRS: Inputs!$B$4
Name TOM_MAX_BEDS: Inputs!$B$2
Name TOM_PRICE: Inputs!$B$3
Name TOTAL_BEDS: Inputs!$B$17
Name TOTAL_FERTILIZER_COST: CostStructure!$B$10
Name TOTAL_FIXED_COST: Optimization!$B$13
Name TOTAL_LABOR_AVAILABLE: Optimization!$B$16
Name TOTAL_LABOR_COST: CostStructure!$B$8
Name TOTAL_LABOR_HRS: CostStructure!$B$2
Name TOTAL_LABOR_USED: Optimization!$B$15
Name TOTAL_PROFIT: Optimization!$B$14
Name TOTAL_REVENUE: Optimization!$B$11
Name TOTAL_VARIABLE_COST: Optimization!$B$12
Name UNUSED_BEDS: Optimization!$B$19
Name UNUSED_LABOR_HOURS: Optimization!$B$17

Sheet Inputs
A1: Name | B1: Value | C1: Unit | D1: Source
A2: TOM_MAX_BEDS | B2: 20 | C2: num beds | D2: Case scenario, crop table
A3: TOM_PRICE | B3: 8800 | C3: USD per bed | D3: Case scenario, crop table
A4: TOM_HRS | B4: 2.5 | C4: hours per week per bed | D4: Case scenario, crop table
A5: TOM_FERT_COST | B5: 880 | C5: USD per bed | D5: Case scenario, crop table
A6: TOM_DIM_PCT | B6: 0.1 | C6: percent per bed | D6: Case scenario, crop table
A7: CAR_MAX_BEDS | B7: 20 | C7: num beds | D7: Case scenario, crop table
A8: CAR_PRICE | B8: 2094 | C8: USD per bed | D8: Case scenario, crop table
A9: CAR_HRS | B9: 0.83333333 | C9: hours per week per bed | D9: Case scenario; displayed as 0.833
A10: CAR_FERT_COST | B10: 440 | C10: USD per bed | D10: Case scenario, crop table
A11: CAR_DIM_PCT | B11: 0.025 | C11: percent per bed | D11: Case scenario, crop table
A12: MES_MAX_BEDS | B12: 30 | C12: num beds | D12: Case scenario, crop table
A13: MES_PRICE | B13: 2700 | C13: USD per bed | D13: Case scenario, crop table
... A27: SEASON_WEEKS | B27: 36 | C27: num weeks | D27: Case scenario

Sheet CostStructure
A1: Metric | B1: Value | C1: Unit
A2: Total Labor Hours | B2: =TOM_BEDS*TOM_HRS*SEASON_WEEKS*(1+TOM_DIM_PCT)^TOM_BEDS+CAR_BEDS*CAR_HRS*SEASON_WEEKS*(1+CAR_DIM_PCT)^CAR_BEDS+MES_BEDS*MES_HRS*SEASON_WEEKS*(1+MES_DIM_PCT)^MES_BEDS -> 5277.2161 | C2: hours
A3: Farmer Hours Used | B3: =MIN(TOTAL_LABOR_HRS,FARMER_HOURS) -> 720 | C3: hours
A4: Temporary Hours Used | B4: =MAX(0,TOTAL_LABOR_HRS-FARMER_HOURS) -> 4557.2161 | C4: hours
A5: Temporary Workers Used | B5: =CEILING(TEMP_HOURS_USED/TEMP_WORKER_HOURS,1) -> 4 | C5: workers
A6: Farmer Labor Cost | B6: =FARMER_HOURS_USED*FARMER_RATE -> 25000 | C6: USD
A7: Temporary Labor Cost | B7: =TEMP_HOURS_USED*TEMP_RATE -> 79118.335 | C7: USD
A8: Total Labor Cost | B8: =FARMER_LABOR_COST+TEMP_LABOR_COST -> 104118.34 | C8: USD
A9: Blended Labor Rate | B9: =IF(TOTAL_LABOR_HRS=0,0,TOTAL_LABOR_COST/TOTAL_LABOR_HRS) -> 19.729784 | C9: USD per hour
A10: Total Fertilizer Cost | B10: =TOM_BEDS*TOM_FERT_COST+CAR_BEDS*CAR_FERT_COST+MES_BEDS*MES_FERT_COST -> 44000 | C10: USD
A11: Total Fixed Cost | B11: =BED_FIXED_COST -> 20000 | C11: USD
A12: Total Variable Cost | B12: =TOTAL_LABOR_COST+TOTAL_FERTILIZER_COST -> 148118.34 | C12: USD
A13: Full-Model Total Cost | B13: =B12+B11 -> 168118.34 | C13: USD

Sheet MCSchedules
A1: Tomatoes Marginal Cost Schedule
A2: q | B2: Labor Hours | C2: Labor Cost | D2: Fertilizer Cost | E2: Total Cost | F2: Marginal Cost | G2: Revenue | H2: Marginal Revenue | I2: Profit Contribution
A3: 0 | B3: =A3*TOM_HRS*SEASON_WEEKS*(1+TOM_DIM_PCT)^A3 -> 0 | C3: =MIN(B3,FARMER_HOURS)*FARMER_RATE+MAX(0,B3-FARMER_HOURS)*TEMP_RATE -> 0 | D3: =A3*TOM_FERT_COST -> 0 | E3: =C3+D3 -> 0 | G3: =A3*TOM_PRICE -> 0 | I3: =G3-E3 -> 0
A4: 1 | B4: =A4*TOM_HRS*SEASON_WEEKS*(1+TOM_DIM_PCT)^A4 -> 99 | C4: =MIN(B4,FARMER_HOURS)*FARMER_RATE+MAX(0,B4-FARMER_HOURS)*TEMP_RATE -> 3437.5 | D4: =A4*TOM_FERT_COST -> 880 | E4: =C4+D4 -> 4317.5 | F4: =E4-E3 -> 4317.5 | G4: =A4*TOM_PRICE -> 8800 | H4: =G4-G3 -> 8800 | I4: =G4-E4 -> 4482.5
A5: 2 | B5: =A5*TOM_HRS*SEASON_WEEKS*(1+TOM_DIM_PCT)^A5 -> 217.8 | C5: =MIN(B5,FARMER_HOURS)*FARMER_RATE+MAX(0,B5-FARMER_HOURS)*TEMP_RATE -> 7562.5 | D5: =A5*TOM_FERT_COST -> 1760 | E5: =C5+D5 -> 9322.5 | F5: =E5-E4 -> 5005 | G5: =A5*TOM_PRICE -> 17600 | H5: =G5-G4 -> 8800 | I5: =G5-E5 -> 8277.5
A6: 3 | B6: =A6*TOM_HRS*SEASON_WEEKS*(1+TOM_DIM_PCT)^A6 -> 359.37 | C6: =MIN(B6,FARMER_HOURS)*FARMER_RATE+MAX(0,B6-FARMER_HOURS)*TEMP_RATE -> 12478.125 | D6: =A6*TOM_FERT_COST -> 2640 | E6: =C6+D6 -> 15118.125 | F6: =E6-E5 -> 5795.625 | G6: =A6*TOM_PRICE -> 26400 | H6: =G6-G5 -> 8800 | I6: =G6-E6 -> 11281.875
A7: 4 | B7: =A7*TOM_HRS*SEASON_WEEKS*(1+TOM_DIM_PCT)^A7 -> 527.076 | C7: =MIN(B7,FARMER_HOURS)*FARMER_RATE+MAX(0,B7-FARMER_HOURS)*TEMP_RATE -> 18301.25 | D7: =A7*TOM_FERT_COST -> 3520 | E7: =C7+D7 -> 21821.25 | F7: =E7-E6 -> 6703.125 | G7: =A7*TOM_PRICE -> 35200 | H7: =G7-G6 -> 8800 | I7: =G7-E7 -> 13378.75
A8: 5 | B8: =A8*TOM_HRS*SEASON_WEEKS*(1+TOM_DIM_PCT)^A8 -> 724.7295 | C8: =MIN(B8,FARMER_HOURS)*FARMER_RATE+MAX(0,B8-FARMER_HOURS)*TEMP_RATE -> 25082.109 | D8: =A8*TOM_FERT_COST -> 4400 | E8: =C8+D8 -> 29482.109 | F8: =E8-E7 -> 7660.8594 | G8: =A8*TOM_PRICE -> 44000 | H8: =G8-G7 -> 8800 | I8: =G8-E8 -> 14517.891
A9: 6 | B9: =A9*TOM_HRS*SEASON_WEEKS*(1+TOM_DIM_PCT)^A9 -> 956.64294 | C9: =MIN(B9,FARMER_HOURS)*FARMER_RATE+MAX(0,B9-FARMER_HOURS)*TEMP_RATE -> 29108.384 | D9: =A9*TOM_FERT_COST -> 5280 | E9: =C9+D9 -> 34388.384 | F9: =E9-E8 -> 4906.275 | G9: =A9*TOM_PRICE -> 52800 | H9: =G9-G8 -> 8800 | I9: =G9-E9 -> 18411.616
A10: 7 | B10: =A10*TOM_HRS*SEASON_WEEKS*(1+TOM_DIM_PCT)^A10 -> 1227.6918 | C10: =MIN(B10,FARMER_HOURS)*FARMER_RATE+MAX(0,B10-FARMER_HOURS)*TEMP_RATE -> 33814.093 | D10: =A10*TOM_FERT_COST -> 6160 | E10: =C10+D10 -> 39974.093 | F10: =E10-E9 -> 5585.7089 | G10: =A10*TOM_PRICE -> 61600 | H10: =G10-G9 -> 8800 | I10: =G10-E10 -> 21625.907
A11: 8 | B11: =A11*TOM_HRS*SEASON_WEEKS*(1+TOM_DIM_PCT)^A11 -> 1543.3839 | C11: =MIN(B11,FARMER_HOURS)*FARMER_RATE+MAX(0,B11-FARMER_HOURS)*TEMP_RATE -> 39294.86 | D11: =A11*TOM_FERT_COST -> 7040 | E11: =C11+D11 -> 46334.86 | F11: =E11-E10 -> 6360.7668 | G11: =A11*TOM_PRICE -> 70400 | H11: =G11-G10 -> 8800 | I11: =G11-E11 -> 24065.14
A12: 9 | B12: =A12*TOM_HRS*SEASON_WEEKS*(1+TOM_DIM_PCT)^A12 -> 1909.9376 | C12: =MIN(B12,FARMER_HOURS)*FARMER_RATE+MAX(0,B12-FARMER_HOURS)*TEMP_RATE -> 45658.639 | D12: =A12*TOM_FERT_COST -> 7920 | E12: =C12+D12 -> 53578.639 | F12: =E12-E11 -> 7243.7793 | G12: =A12*TOM_PRICE -> 79200 | H12: =G12-G11 -> 8800 | I12: =G12-E12 -> 25621.361
A13: 10 | B13: =A13*TOM_HRS*SEASON_WEEKS*(1+TOM_DIM_PCT)^A13 -> 2334.3682 | C13: =MIN(B13,FARMER_HOURS)*FARMER_RATE+MAX(0,B13-FARMER_HOURS)*TEMP_RATE -> 53027.226 | D13: =A13*TOM_FERT_COST -> 8800 | E13: =C13+D13 -> 61827.226 | F13: =E13-E12 -> 8248.5865 | G13: =A13*TOM_PRICE -> 88000 | H13: =G13-G12 -> 8800 | I13: =G13-E13 -> 26172.774
A14: 11 | B14: =A14*TOM_HRS*SEASON_WEEKS*(1+TOM_DIM_PCT)^A14 -> 2824.5855 | C14: =MIN(B14,FARMER_HOURS)*FARMER_RATE+MAX(0,B14-FARMER_HOURS)*TEMP_RATE -> 61537.943 | D14: =A14*TOM_FERT_COST -> 9680 | E14: =C14+D14 -> 71217.943 | F14: =E14-E13 -> 9390.7174 | G14: =A14*TOM_PRICE -> 96800 | H14: =G14-G13 -> 8800 | I14: =G14-E14 -> 25582.057
A15: 12 | B15: =A15*TOM_HRS*SEASON_WEEKS*(1+TOM_DIM_PCT)^A15 -> 3389.5026 | C15: =MIN(B15,FARMER_HOURS)*FARMER_RATE+MAX(0,B15-FARMER_HOURS)*TEMP_RATE -> 71345.532 | D15: =A15*TOM_FERT_COST -> 10560 | E15: =C15+D15 -> 81905.532 | F15: =E15-E14 -> 10687.589 | G15: =A15*TOM_PRICE -> 105600 | H15: =G15-G14 -> 8800 | I15: =G15-E15 -> 23694.468
... A23: 20 | B23: =A23*TOM_HRS*SEASON_WEEKS*(1+TOM_DIM_PCT)^A23 -> 12109.5 | C23: =MIN(B23,FARMER_HOURS)*FARMER_RATE+MAX(0,B23-FARMER_HOURS)*TEMP_RATE -> 222734.37 | D23: =A23*TOM_FERT_COST -> 17600 | E23: =C23+D23 -> 240334.37 | F23: =E23-E22 -> 29548.324 | G23: =A23*TOM_PRICE -> 176000 | H23: =G23-G22 -> 8800 | I23: =G23-E23 -> -64334.373
A25: Carrots Marginal Cost Schedule
A26: q | B26: Labor Hours | C26: Labor Cost | D26: Fertilizer Cost | E26: Total Cost | F26: Marginal Cost | G26: Revenue | H26: Marginal Revenue | I26: Profit Contribution
A27: 0 | B27: =A27*CAR_HRS*SEASON_WEEKS*(1+CAR_DIM_PCT)^A27 -> 0 | C27: =MIN(B27,FARMER_HOURS)*FARMER_RATE+MAX(0,B27-FARMER_HOURS)*TEMP_RATE -> 0 | D27: =A27*CAR_FERT_COST -> 0 | E27: =C27+D27 -> 0 | G27: =A27*CAR_PRICE -> 0 | I27: =G27-E27 -> 0
A28: 1 | B28: =A28*CAR_HRS*SEASON_WEEKS*(1+CAR_DIM_PCT)^A28 -> 30.75 | C28: =MIN(B28,FARMER_HOURS)*FARMER_RATE+MAX(0,B28-FARMER_HOURS)*TEMP_RATE -> 1067.7083 | D28: =A28*CAR_FERT_COST -> 440 | E28: =C28+D28 -> 1507.7083 | F28: =E28-E27 -> 1507.7083 | G28: =A28*CAR_PRICE -> 2094 | H28: =G28-G27 -> 2094 | I28: =G28-E28 -> 586.29167
A29: 2 | B29: =A29*CAR_HRS*SEASON_WEEKS*(1+CAR_DIM_PCT)^A29 -> 63.0375 | C29: =MIN(B29,FARMER_HOURS)*FARMER_RATE+MAX(0,B29-FARMER_HOURS)*TEMP_RATE -> 2188.8021 | D29: =A29*CAR_FERT_COST -> 880 | E29: =C29+D29 -> 3068.8021 | F29: =E29-E28 -> 1561.0937 | G29: =A29*CAR_PRICE -> 4188 | H29: =G29-G28 -> 2094 | I29: =G29-E29 -> 1119.1979
A30: 3 | B30: =A30*CAR_HRS*SEASON_WEEKS*(1+CAR_DIM_PCT)^A30 -> 96.920156 | C30: =MIN(B30,FARMER_HOURS)*FARMER_RATE+MAX(0,B30-FARMER_HOURS)*TEMP_RATE -> 3365.2832 | D30: =A30*CAR_FERT_COST -> 1320 | E30: =C30+D30 -> 4685.2832 | F30: =E30-E29 -> 1616.4811 | G30: =A30*CAR_PRICE -> 6282 | H30: =G30-G29 -> 2094 | I30: =G30-E30 -> 1596.7168
A31: 4 | B31: =A31*CAR_HRS*SEASON_WEEKS*(1+CAR_DIM_PCT)^A31 -> 132.45755 | C31: =MIN(B31,FARMER_HOURS)*FARMER_RATE+MAX(0,B31-FARMER_HOURS)*TEMP_RATE -> 4599.2204 | D31: =A31*CAR_FERT_COST -> 1760 | E31: =C31+D31 -> 6359.2204 | F31: =E31-E30 -> 1673.9372 | G31: =A31*CAR_PRICE -> 8376 | H31: =G31-G30 -> 2094 | I31: =G31-E31 -> 2016.7796
A32: 5 | B32: =A32*CAR_HRS*SEASON_WEEKS*(1+CAR_DIM_PCT)^A32 -> 169.71123 | C32: =MIN(B32,FARMER_HOURS)*FARMER_RATE+MAX(0,B32-FARMER_HOURS)*TEMP_RATE -> 5892.7511 | D32: =A32*CAR_FERT_COST -> 2200 | E32: =C32+D32 -> 8092.7511 | F32: =E32-E31 -> 1733.5307 | G32: =A32*CAR_PRICE -> 10470 | H32: =G32-G31 -> 2094 | I32: =G32-E32 -> 2377.2489
A33: 6 | B33: =A33*CAR_HRS*SEASON_WEEKS*(1+CAR_DIM_PCT)^A33 -> 208.74482 | C33: =MIN(B33,FARMER_HOURS)*FARMER_RATE+MAX(0,B33-FARMER_HOURS)*TEMP_RATE -> 7248.0839 | D33: =A33*CAR_FERT_COST -> 2640 | E33: =C33+D33 -> 9888.0839 | F33: =E33-E32 -> 1795.3328 | G33: =A33*CAR_PRICE -> 12564 | H33: =G33-G32 -> 2094 | I33: =G33-E33 -> 2675.9161
A34: 7 | B34: =A34*CAR_HRS*SEASON_WEEKS*(1+CAR_DIM_PCT)^A34 -> 249.62401 | C34: =MIN(B34,FARMER_HOURS)*FARMER_RATE+MAX(0,B34-FARMER_HOURS)*TEMP_RATE -> 8667.5003 | D34: =A34*CAR_FERT_COST -> 3080 | E34: =C34+D34 -> 11747.5 | F34: =E34-E33 -> 1859.4164 | G34: =A34*CAR_PRICE -> 14658 | H34: =G34-G33 -> 2094 | I34: =G34-E34 -> 2910.4997
A35: 8 | B35: =A35*CAR_HRS*SEASON_WEEKS*(1+CAR_DIM_PCT)^A35 -> 292.4167 | C35: =MIN(B35,FARMER_HOURS)*FARMER_RATE+MAX(0,B35-FARMER_HOURS)*TEMP_RATE -> 10153.357 | D35: =A35*CAR_FERT_COST -> 3520 | E35: =C35+D35 -> 13673.357 | F35: =E35-E34 -> 1925.8572 | G35: =A35*CAR_PRICE -> 16752 | H35: =G35-G34 -> 2094 | I35: =G35-E35 -> 3078.6425
A36: 9 | B36: =A36*CAR_HRS*SEASON_WEEKS*(1+CAR_DIM_PCT)^A36 -> 337.193 | C36: =MIN(B36,FARMER_HOURS)*FARMER_RATE+MAX(0,B36-FARMER_HOURS)*TEMP_RATE -> 11708.09 | D36: =A36*CAR_FERT_COST -> 3960 | E36: =C36+D36 -> 15668.09 | F36: =E36-E35 -> 1994.7329 | G36: =A36*CAR_PRICE -> 18846 | H36: =G36-G35 -> 2094 | I36: =G36-E36 -> 3177.9097
A37: 10 | B37: =A37*CAR_HRS*SEASON_WEEKS*(1+CAR_DIM_PCT)^A37 -> 384.02536 | C37: =MIN(B37,FARMER_HOURS)*FARMER_RATE+MAX(0,B37-FARMER_HOURS)*TEMP_RATE -> 13334.214 | D37: =A37*CAR_FERT_COST -> 4400 | E37: =C37+D37 -> 17734.214 | F37: =E37-E36 -> 2066.1237 | G37: =A37*CAR_PRICE -> 20940 | H37: =G37-G36 -> 2094 | I37: =G37-E37 -> 3205.786
A38: 11 | B38: =A38*CAR_HRS*SEASON_WEEKS*(1+CAR_DIM_PCT)^A38 -> 432.9886 | C38: =MIN(B38,FARMER_HOURS)*FARMER_RATE+MAX(0,B38-FARMER_HOURS)*TEMP_RATE -> 15034.326 | D38: =A38*CAR_FERT_COST -> 4840 | E38: =C38+D38 -> 19874.326 | F38: =E38-E37 -> 2140.1123 | G38: =A38*CAR_PRICE -> 23034 | H38: =G38-G37 -> 2094 | I38: =G38-E38 -> 3159.6737
A39: 12 | B39: =A39*CAR_HRS*SEASON_WEEKS*(1+CAR_DIM_PCT)^A39 -> 484.15998 | C39: =MIN(B39,FARMER_HOURS)*FARMER_RATE+MAX(0,B39-FARMER_HOURS)*TEMP_RATE -> 16811.11 | D39: =A39*CAR_FERT_COST -> 5280 | E39: =C39+D39 -> 22091.11 | F39: =E39-E38 -> 2216.784 | G39: =A39*CAR_PRICE -> 25128 | H39: =G39-G38 -> 2094 | I39: =G39-E39 -> 3036.8897
... A47: 20 | B47: =A47*CAR_HRS*SEASON_WEEKS*(1+CAR_DIM_PCT)^A47 -> 983.16986 | C47: =MIN(B47,FARMER_HOURS)*FARMER_RATE+MAX(0,B47-FARMER_HOURS)*TEMP_RATE -> 29568.921 | D47: =A47*CAR_FERT_COST -> 8800 | E47: =C47+D47 -> 38368.921 | F47: =E47-E46 -> 1688.9455 | G47: =A47*CAR_PRICE -> 41880 | H47: =G47-G46 -> 2094 | I47: =G47-E47 -> 3511.0787
A49: Mesclun Marginal Cost Schedule
A50: q | B50: Labor Hours | C50: Labor Cost | D50: Fertilizer Cost | E50: Total Cost | F50: Marginal Cost | G50: Revenue | H50: Marginal Revenue | I50: Profit Contribution
A51: 0 | B51: =A51*MES_HRS*SEASON_WEEKS*(1+MES_DIM_PCT)^A51 -> 0 | C51: =MIN(B51,FARMER_HOURS)*FARMER_RATE+MAX(0,B51-FARMER_HOURS)*TEMP_RATE -> 0 | D51: =A51*MES_FERT_COST -> 0 | E51: =C51+D51 -> 0 | G51: =A51*MES_PRICE -> 0 | I51: =G51-E51 -> 0
A52: 1 | B52: =A52*MES_HRS*SEASON_WEEKS*(1+MES_DIM_PCT)^A52 -> 45.5625 | C52: =MIN(B52,FARMER_HOURS)*FARMER_RATE+MAX(0,B52-FARMER_HOURS)*TEMP_RATE -> 1582.0312 | D52: =A52*MES_FERT_COST -> 880 | E52: =C52+D52 -> 2462.0312 | F52: =E52-E51 -> 2462.0312 | G52: =A52*MES_PRICE -> 2700 | H52: =G52-G51 -> 2700 | I52: =G52-E52 -> 237.96875
A53: 2 | B53: =A53*MES_HRS*SEASON_WEEKS*(1+MES_DIM_PCT)^A53 -> 92.264062 | C53: =MIN(B53,FARMER_HOURS)*FARMER_RATE+MAX(0,B53-FARMER_HOURS)*TEMP_RATE -> 3203.6133 | D53: =A53*MES_FERT_COST -> 1760 | E53: =C53+D53 -> 4963.6133 | F53: =E53-E52 -> 2501.582 | G53: =A53*MES_PRICE -> 5400 | H53: =G53-G52 -> 2700 | I53: =G53-E53 -> 436.38672
A54: 3 | B54: =A54*MES_HRS*SEASON_WEEKS*(1+MES_DIM_PCT)^A54 -> 140.12604 | C54: =MIN(B54,FARMER_HOURS)*FARMER_RATE+MAX(0,B54-FARMER_HOURS)*TEMP_RATE -> 4865.4877 | D54: =A54*MES_FERT_COST -> 2640 | E54: =C54+D54 -> 7505.4877 | F54: =E54-E53 -> 2541.8744 | G54: =A54*MES_PRICE -> 8100 | H54: =G54-G53 -> 2700 | I54: =G54-E54 -> 594.51233
A55: 4 | B55: =A55*MES_HRS*SEASON_WEEKS*(1+MES_DIM_PCT)^A55 -> 189.17016 | C55: =MIN(B55,FARMER_HOURS)*FARMER_RATE+MAX(0,B55-FARMER_HOURS)*TEMP_RATE -> 6568.4084 | D55: =A55*MES_FERT_COST -> 3520 | E55: =C55+D55 -> 10088.408 | F55: =E55-E54 -> 2582.9207 | G55: =A55*MES_PRICE -> 10800 | H55: =G55-G54 -> 2700 | I55: =G55-E55 -> 711.59164
A56: 5 | B56: =A56*MES_HRS*SEASON_WEEKS*(1+MES_DIM_PCT)^A56 -> 239.41848 | C56: =MIN(B56,FARMER_HOURS)*FARMER_RATE+MAX(0,B56-FARMER_HOURS)*TEMP_RATE -> 8313.1418 | D56: =A56*MES_FERT_COST -> 4400 | E56: =C56+D56 -> 12713.142 | F56: =E56-E55 -> 2624.7335 | G56: =A56*MES_PRICE -> 13500 | H56: =G56-G55 -> 2700 | I56: =G56-E56 -> 786.85817
...

Sheet Optimization
A1: Decision Variables
A2: Tomato Beds | B2: 10
A3: Carrot Beds | B3: 20
A4: Mesclun Beds | B4: 30
A7: Required Outputs
A8: Optimal Tomato Beds | B8: =TOM_BEDS -> 10
A9: Optimal Carrot Beds | B9: =CAR_BEDS -> 20
A10: Optimal Mesclun Beds | B10: =MES_BEDS -> 30
A11: Total Revenue | B11: =TOM_BEDS*TOM_PRICE+CAR_BEDS*CAR_PRICE+MES_BEDS*MES_PRICE -> 210880
A12: Total Variable Cost | B12: =CostStructure!B12 -> 148118.34
A13: Total Fixed Cost | B13: =CostStructure!B11 -> 20000
A14: Total Profit | B14: =TOTAL_REVENUE-TOTAL_VARIABLE_COST-TOTAL_FIXED_COST -> 42761.665
A15: Total Labor Used | B15: =TOTAL_LABOR_HRS -> 5277.2161
A16: Total Labor Available | B16: =FARMER_HOURS+MAX_TEMP_WORKERS*TEMP_WORKER_HOURS -> 6480
A17: Unused Labor Hours | B17: =TOTAL_LABOR_AVAILABLE-TOTAL_LABOR_USED -> 1202.7839
A18: Temporary Workers Used | B18: =CostStructure!B5 -> 4
A19: Unused Beds | B19: =TOTAL_BEDS-(TOM_BEDS+CAR_BEDS+MES_BEDS) -> 4
A21: Acceptance Status | B21: RUN | C21: Change to RUN after Solver completes and the workbook is recalculated.
A23: Constraint Calculations
A24: Constraint | B24: Used | C24: Limit | D24: Slack / Variance | E24: Status
A25: Tomato maximum | B25: =TOM_BEDS -> 10 | C25: =TOM_MAX_BEDS -> 20 | D25: =C25-B25 -> 10 | E25: =IF(D25>=0,"PASS","FAIL") -> PASS
A26: Carrot maximum | B26: =CAR_BEDS -> 20 | C26: =CAR_MAX_BEDS -> 20 | D26: =C26-B26 -> 0 | E26: =IF(D26>=0,"PASS","FAIL") -> PASS
A27: Mesclun maximum | B27: =MES_BEDS -> 30 | C27: =MES_MAX_BEDS -> 30 | D27: =C27-B27 -> 0 | E27: =IF(D27>=0,"PASS","FAIL") -> PASS
A28: Total land | B28: =TOM_BEDS+CAR_BEDS+MES_BEDS -> 60 | C28: =TOTAL_BEDS -> 64 | D28: =C28-B28 -> 4 | E28: =IF(D28>=0,"PASS","FAIL") -> PASS
A29: Temporary labor capacity | B29: =TEMP_HOURS_USED -> 4557.2161 | C29: =MAX_TEMP_WORKERS*TEMP_WORKER_HOURS -> 5760 | D29: =C29-B29 -> 1202.7839 | E29: =IF(D29>=0,"PASS","FAIL") -> PASS
A30: Tomato nonnegative | B30: =TOM_BEDS -> 10 | C30: =0 -> 0 | D30: =B30-C30 -> 10 | E30: =IF(D30>=0,"PASS","FAIL") -> PASS
A31: Carrot nonnegative | B31: =CAR_BEDS -> 20 | C31: =0 -> 0 | D31: =B31-C31 -> 20 | E31: =IF(D31>=0,"PASS","FAIL") -> PASS
A32: Mesclun nonnegative | B32: =MES_BEDS -> 30 | C32: =0 -> 0 | D32: =B32-C32 -> 30 | E32: =IF(D32>=0,"PASS","FAIL") -> PASS
A33: Tomato integer | B33: =TOM_BEDS -> 10 | C33: ="Integer" -> Integer | D33: =MOD(B33,1) -> 0 | E33: =IF(D33=0,"PASS","FAIL") -> PASS
A34: Carrot integer | B34: =CAR_BEDS -> 20 | C34: ="Integer" -> Integer | D34: =MOD(B34,1) -> 0 | E34: =IF(D34=0,"PASS","FAIL") -> PASS
A35: Mesclun integer | B35: =MES_BEDS -> 30 | C35: ="Integer" -> Integer | D35: =MOD(B35,1) -> 0 | E35: =IF(D35=0,"PASS","FAIL") -> PASS
A38: Solver Setup
A39: Objective | B39: TOTAL_PROFIT
A40: Optimize | B40: Maximize
A41: Changing Cells | B41: TOM_BEDS, CAR_BEDS, MES_BEDS
A42: Method | B42: GRG Nonlinear
A43: Constraint 1 | B43: TOM_BEDS <= TOM_MAX_BEDS
A44: Constraint 2 | B44: CAR_BEDS <= CAR_MAX_BEDS
A45: Constraint 3 | B45: MES_BEDS <= MES_MAX_BEDS
A46: Constraint 4 | B46: TOM_BEDS + CAR_BEDS + MES_BEDS <= TOTAL_BEDS
...

Sheet Checks
A1: Validation Rule | B1: Expected Result | C1: Actual Result | D1: PASS/FAIL
A2: No spreadsheet error cells | B2: No errors | C2: =IF(SUMPRODUCT(--ISERROR(CostStructure!B2:B13))+SUMPRODUCT(--ISERROR(MCSchedules!B3:I23))+SUMPRODUCT(--ISERROR(MCSchedules!B27:I47))+SUMPRODUCT(--ISERROR(MCSchedules!B51:I81))+SUMPRODUCT(--ISERROR(Optimization!B8:E35))=0,"No errors","Errors found") -> No errors | D2: =IF(C2=B2,"PASS","FAIL") -> PASS
A3: Every designated calculated cell contains a formula | B3: 646 formula cells | C3: {=SUMPRODUCT(--_xlfn.ISFORMULA(CostStructure!B2:B13))+SUMPRODUCT(--_xlfn.ISFORMULA(MCSchedules!B3:I23))+SUMPRODUCT(--_xlfn.ISFORMULA(MCSchedules!B27:I47))+SUMPRODUCT(--_xlfn.ISFORMULA(MCSchedules!B51:I81))+SUMPRODUCT(--_xlfn.ISFORMULA(Optimization!B8:B19))+SUMPRODUCT(--_xlfn.ISFORMULA(Optimization!B25:E35))&" formula cells"} -> 646 formula cells | D3: =IF(C3=B3,"PASS","FAIL") -> PASS
A4: Every input Value cell contains a constant | B4: 26 constants | C4: {=COUNT(Inputs!B2:B27)-SUMPRODUCT(--_xlfn.ISFORMULA(Inputs!B2:B27))&" constants"} -> 26 constants | D4: =IF(C4=B4,"PASS","FAIL") -> PASS
A5: Total allocated beds <= TOTAL_BEDS | B5: TRUE | C5: =TOM_BEDS+CAR_BEDS+MES_BEDS<=TOTAL_BEDS -> TRUE | D5: =IF(C5=B5,"PASS","FAIL") -> PASS
A6: Tomato allocation <= TOM_MAX_BEDS | B6: TRUE | C6: =TOM_BEDS<=TOM_MAX_BEDS -> TRUE | D6: =IF(C6=B6,"PASS","FAIL") -> PASS
A7: Carrot allocation <= CAR_MAX_BEDS | B7: TRUE | C7: =CAR_BEDS<=CAR_MAX_BEDS -> TRUE | D7: =IF(C7=B7,"PASS","FAIL") -> PASS
A8: Mesclun allocation <= MES_MAX_BEDS | B8: TRUE | C8: =MES_BEDS<=MES_MAX_BEDS -> TRUE | D8: =IF(C8=B8,"PASS","FAIL") -> PASS
A9: Tomato allocation >= 0 | B9: TRUE | C9: =TOM_BEDS>=0 -> TRUE | D9: =IF(C9=B9,"PASS","FAIL") -> PASS
A10: Carrot allocation >= 0 | B10: TRUE | C10: =CAR_BEDS>=0 -> TRUE | D10: =IF(C10=B10,"PASS","FAIL") -> PASS
A11: Mesclun allocation >= 0 | B11: TRUE | C11: =MES_BEDS>=0 -> TRUE | D11: =IF(C11=B11,"PASS","FAIL") -> PASS
A12: Optimal tomato beds = 10 | B12: 10 | C12: =IF(Optimization!B21="RUN",OPT_TOM_BEDS,"NOT EVALUATED") -> 10 | D12: =IF(C12="NOT EVALUATED","NOT EVALUATED",IF(C12=B12,"PASS","FAIL")) -> PASS
A13: Optimal carrot beds = 20 | B13: 20 | C13: =IF(Optimization!B21="RUN",OPT_CAR_BEDS,"NOT EVALUATED") -> 20 | D13: =IF(C13="NOT EVALUATED","NOT EVALUATED",IF(C13=B13,"PASS","FAIL")) -> PASS
A14: Optimal mesclun beds = 30 | B14: 30 | C14: =IF(Optimization!B21="RUN",OPT_MES_BEDS,"NOT EVALUATED") -> 30 | D14: =IF(C14="NOT EVALUATED","NOT EVALUATED",IF(C14=B14,"PASS","FAIL")) -> PASS
A15: Season profit = $42,762 +/- $5 | B15: $42,757 to $42,767 | C15: =IF(Optimization!B21="RUN",TOTAL_PROFIT,"NOT EVALUATED") -> 42761.665 | D15: =IF(C15="NOT EVALUATED","NOT EVALUATED",IF(ABS(C15-42762)<=5,"PASS","FAIL")) -> PASS
A16: Tomato labor hours at q = 1 equals 99 | B16: 99 | C16: =MCSchedules!B4 -> 99 | D16: =IF(ABS(C16-B16)<0.000001,"PASS","FAIL") -> PASS
A19: Audit Findings
A20: What was checked | B20: What was found | C20: Action taken | D20: Result
A21: Acceptance mathematics | B21: The specified formulas produce 10 tomato, 20 carrot, and 30 mesclun beds with profit of $42,761.66. | C21: Implemented formulas exactly as approved. | D21: Consistent
A22: Temporary labor costing | B22: The acceptance result requires hourly temporary labor cost; workers used is a staffing/capacity metric. | C22: Used TEMP_HOURS_USED x TEMP_RATE for cost and CEILING only for workers required. | D22: Resolved
A23: Farmer labor costing | B23: Farmer cost is based on hours used at FARMER_RATE, not the full salary. | C23: Implemented FARMER_HOURS_USED x FARMER_RATE. | D23: Resolved
A24: Schedule definitions | B24: Marginal revenue and profit contribution were not explicit. | C24: Used change in revenue for MR and revenue less schedule total cost for contribution. | D24: Resolved
A25: Initial acceptance state | B25: Decision variables must start at zero, so optimum checks cannot initially pass. | C25: Added NOT RUN/RUN control; optimum checks show NOT EVALUATED until RUN. | D25: Resolved
A26: Solver handoff | B26: A macro-free workbook needs a visible, reproducible Solver specification. | C26: Added the complete Solver Setup section on Optimization. | D26: Documented
